Workbook

Sheet Sheet1
A1: Phone Number | B1: Destination | C1: Products | D1: Quantity | E1: Dispatch Date
A2: 8035019487 | B2: Onitsha | C2: ulcer tea | D2: 2 | E2: 24/6/2026
A3: 8035019487 | B3: Onitsha | C3: Slimming tea | D3: 2 | E3: 24/6/2026
A4: 8035019487 | B4: Onitsha | C4: Tea for men | D4: 2 | E4: 24/6/2026 | H4: tea for men
A5: 8065538774 | B5: Ayatala/Ija Lagos | C5: postrate tea | D5: 1 | E5: 24/6/2026
A6: 8065538774 | B6: Ayatala/Ija Lagos | C6: Sugar tea's | D6: 1 | E6: 24/6/2026
A7: 8036743639 | B7: ABA | C7: Pillow | D7: 2 | E7: 27/6/2026
A8: 8036743639 | B8: ABA | C8: Ulcer-tea | D8: 1 | E8: 27/6/2026
A9: 8036743639 | B9: ABA | C9: Sperm booster | D9: 1 | E9: 27/6/2026
A10: 8037379461 | B10: Bayelsa | C10: Cholestrol | D10: 4 | E10: 27/6/2026
A11: 8140043724 | B11: Lagos Ijobaye | C11: ulcer tea | D11: 1 | E11: 28/6/2026
A12: 7029964824 | B12: ABA | C12: ulcer tea | D12: 1 | E12: 27/6/2026
A13: 7030968451 | B13: mazamaza lash first | C13: Slimming tea | D13: 2 | E13: 29/6/2026
A14: 7030968451 | B14: mazamaza lash first | C14: infection-tea | D14: 2 | E14: 29/6/2026
A15: 7030968451 | B15: First lash | C15: Tea for men | D15: 2 | E15: 29/6/2026
A16: 8039361062 | B16: Port harcourt | C16: BP tea | D16: 1 | E16: 29/6/2026
... A25: 9020016225 | B25: ABA | C25: Sugar Tea | D25: 1 | E25: 30/6/2026
A26: 8161725902 | B26: ABA | C26: BP tea | D26: 1 | E26: 46029
A27: 8068797832 | B27: Onitsha | C27: Sugar tea | D27: 1 | E27: 46029
A28: 8068797832 | B28: Onitsha | C28: Ulcer | D28: 1 | E28: 46029
A29: 7069202677 | B29: Enugu | C29: Sugar tea | D29: 1 | E29: 46029
A30: 7069202677 | B30: Enugu | C30: BP tea | D30: 1 | E30: 46029
A31: 8037815531 | B31: Lagos alaba | C31: Sugar tea | D31: 1 | E31: 46060
A32: 8037432361 | B32: mazamaza Lagos | C32: postrate-tea | D32: 1 | E32: 46060
A33: 8037432361 | B33: mazamaza | C33: Sugar | D33: 1 | E33: 46060

Sheet dispatch_ledger (1)
A1: Phone Number | B1: Destination | C1: Products | D1: Quantity | E1: Dispatch Date
A2: 8037433367 | B2: Onitsha/Lagos | C2: Kidney tea | D2: 1 | E2: 46060
A3: 803365247158 | B3: North Carolina USA | C3: BP Tea | D3: 4 | E3: 46088
A4: +1(336)5247158 | B4: North Carolina USA | C4: Sugar Tea | D4: 4 | E4: 46088
A5: +1(336)5247158 | B5: North Carolina USA | C5: Sperm Booster | D5: 1 | E5: 46088
A6: 8067155115 | B6: Abba Gana | C6: Solar Green | D6: 3 | E6: 46088
A7: 8069155175 | B7: Enugu | C7: Small Solar G. | D7: 1 | E7: 46088
A8: 8063637793 | B8: Umuahia | C8: Slimming tea | D8: 2 | E8: 46180
B9: Umuahia | C9: Sugar Tea | D9: 2 | E9: 46180
A10: 70331298913 | B10: Enugu | C10: Indigestion Ts | D10: 1 | E10: 46180
A11: 7033129893 | B11: Enugu | C11: Slimming tea | D11: 1 | E11: 46180
A12: 8055987440 | B12: ABA | C12: Ulcer | D12: 1 | E12: 46180
A13: 8105593152 | B13: ABA | C13: Sugar tea | D13: 1 | E13: 46180
B14: Akwa Ibom | C14: Slimming tea | D14: 1 | E14: 46180
B15: Akwa Ibom | C15: Tea for men | D15: 2 | E15: 46180
B16: Enugu | C16: Infection Chon | D16: 1 | E16: 46180
B17: Enugu | C17: Fibroid tea | D17: 1 | E17: 46180
B18: Enugu | C18: BP Tea | D18: 1 | E18: 46180
A19: 2034731166 | B19: ABA | C19: Prostate | D19: 2 | E19: 46210
A20: 8032587950 | B20: Abuja | C20: Prostate | D20: 1 | E20: 46210
A21: 8060681137 | B21: Enugu | C21: Tea for men | D21: 1 | E21: 46210
A22: 8141362251 | B22: Lagos | C22: Sperm Booster | D22: 1 | E22: 46210
A23: 8037 | B23: Akwa Ibom | C23: Sugar | D23: 1 | E23: 46210
B24: 151, Agu Dimdun | C24: Sugar | D24: 1 | E24: 46210
A25: 8069155175 | B25: ABA | C25: Solar Green | D25: 1 | E25: 46210
A26: 8069155175 | B26: ABA | C26: Lavender skin | D26: 1 | E26: 46210
A27: 704458442 | B27: PH Water Line ABA | C27: Liver Cleanse | D27: 1 | E27: 46210
A28: 7044817710 | B28: PH Water Line | C28: Prostate | D28: 1 | E28: 46241
A29: 8034047224 | B29: ABA | C29: Small blender | D29: 1 | E29: 46241
A30: 9169449197 | B30: Awka | C30: Small blender | D30: 1 | E30: 46241
A31: 8063002287 | B31: PH Water Line | C31: Cholesterol | D31: 3 | E31: 46241
A32: 8063002287 | B32: PH Water Line | C32: Ulcer Tea | D32: 2 | E32: 46241

Sheet Sheet2
A1: Phone Number | B1: Destination | C1: Product | D1: Quantity Dispatched | E1: Date
A2: 9030910073 | B2: Enugu | C2: Infection | D2: 1 | E2: 46303
A3: 9030910073 | B3: Enugu | C3: Sugar Tea | D3: 1 | E3: 46303
A4: 7024852183 | B4: Lagos | C4: Ulc | D4: 1 | E4: 46303
A5: 7039450433 | B5: Enugu | C5: Sugar | D5: 2 | E5: 46334
B6: Asaba | C6: Slimming | D6: 1 | E6: 46334
B7: Asaba | C7: Prost | D7: 2 | E7: 46334
A8: 8024213214 | B8: Aba | C8: Prost | D8: 2 | E8: 46334
A9: 8163854758 | B9: Umuahia | C9: Ulcer | D9: 1 | E9: 46364
A10: 8061672050 | B10: Asaba | C10: Cholestrol | D10: 1 | E10: 46364
A11: 8163854758 | B11: Umuahia | C11: Infection | D11: 1 | E11: 46364
A12: 8163854758 | B12: Umuahia | C12: Liver Tea | D12: 1 | E12: 46364
A13: 7080910093 | B13: Enugu | C13: Slimming Tea | D13: 1 | E13: 46364
A14: 7030910073 | B14: Enugu | C14: Infection Tea | D14: 1 | E14: 46364
A15: 7036363534 | B15: Lagos, Mainland | C15: Immune Booster | D15: 1 | E15: 46364
A16: 8032151901 | B16: Lagos Egbeda | C16: Diabb | D16: 1 | E16: 46364
A17: 8032151901 | B17: Lagos Egbeda | C17: Slimming Tea | D17: 1 | E17: 13/8/2026
A18: 803251901 | B18: Lagos Egbeda | C18: BP Tea | D18: 1 | E18: 13/8/2026
C19: Sperm Booster | D19: 1 | E19: 13/8/2026
A20: 9054606524 | B20: Aba, Abia state | C20: Infection Tea | D20: 2 | E20: 17/8/2026
A21: 8065538714 | B21: Iyamho, Lagos | C21: Bp Tea | D21: 2 | E21: 17/8/2026
A22: 8033258175 | B22: Mushin, Lagos | C22: Ulcer Tea | D22: 1 | E22: 17/8/2026
A23: 8163854758 | B23: Umuahia, Abia state | C23: Tea for men | D23: 1 sachet | E23: 20/8/2026
A24: 9165854758 | C24: Ulcer Tea | D24: 1 sachet | E24: 20/8/2026
C25: Cholesterol Tea | D25: 1 sachet | E25: 20/8/2026
A26: 9034606524 | B26: Aba, Abia state | C26: Infection Tea | D26: 1 sachet | E26: 24/8/2026
C27: Sperm booster | D27: 1 Tin | E27: 24/8/2026
C28: Tea for Men | D28: 1 sachet | E28: 24/8/2026
A29: 8033218819 | B29: Lagos | C29: Prostrate Tea | D29: 1 sachet | E29: 24/8/2026
C30: Bp Tea | D30: 1 sachet | E30: 24/8/2026
C31: Ulcer Tea | D31: 1 sachet | E31: 24/8/2026
A32: 8163005469 | B32: Lagos | C32: Tea for Kidney | D32: 1 Tin | E32: 24/8/2026
A33: 806495955 | B33: Ajah, Lagos | C33: Tea for Liver | D33: 1 sachet | E33: 24/8/2026

Sheet Sheet6
A1: Phone Number | B1: Destination | C1: Products | D1: Quantity | E1: Dispatch Date
A2: 07026726707, 07026726204 | B2: Lagos Malasolu | C2: Tea for men | D2: 2 | E2: 15/7/2026
B3: Lagos Malasolu | C3: Injection tea | D3: 1 | E3: 15/7/2026
B4: Olu | C4: ulcer tea | D4: 2 | E4: 15/7/2026
C5: infertility tea | D5: 1 | E5: 15/7/2026
A6: 8146868132 | B6: NSUKKA | C6: Diabetes Tea | D6: 1 | E6: 15/7/2026
A7: 91163472705 | B7: Asaba | C7: catarrh Tea | D7: 1 | E7: 16/7/2026
A8: 7063472705 | B8: Asaba | C8: Slimming tea | D8: 1 | E8: 16/7/2026
A9: 91163472705 | B9: Asaba | C9: BP tea | D9: 1 | E9: 16/7/2026
A10: 8032220343 | B10: Onitsha | C10: ulcer | D10: 1 | E10: 16/7/2026
A11: 7060543708 | B11: Enugu | C11: Ulcer | D11: 1 | E11: 16/7/2026
A12: 7060543708 | B12: Enugu | C12: diabetes | D12: 1 | E12: 16/7/2026
A13: 9032534163 | B13: Okla | C13: Ulcer | D13: 2 | E13: 16/7/2026
A14: 9032534163 | B14: Orlu | C14: Light | D14: 2 | E14: 16/7/2026
A15: 8039667706 | B15: Abuja | C15: Tea for men | D15: 1 | E15: 17/12/2026
A16: 8039667706 | B16: Abuja | C16: injection | D16: 1 | E16: 17/12/2026
C17: SLimming Tea | D17: 3 | E17: 20/7/2026
A18: 8097089018 | B18: Lagos, Alafia | C18: Injection tea | D18: 1 | E18: 21/7/2026
A19: 8097089018 | B19: Lagos, Alafia | C19: Tea for men | D19: 1 | E19: 21/7/2026
A20: 8097089018 | B20: Lagos, Alafia | C20: Sugar Tea | D20: 1 | E20: 21/7/2026
A21: 8097089018 | B21: Lagos, Alafia | C21: Prostrate tea | D21: 1 | E21: 21/7/2026
A22: 8097089018 | B22: Lagos, Alafia | C22: Juice Extractor | D22: 1 | E22: 21/7/2026
A23: 7067900985 | B23: Enugu | C23: Sugar Tea | D23: 1 | E23: 21/7/2026
A24: 7067900985 | B24: Enugu | C24: Cholestrol tea | D24: 1 | E24: 21/7/2026
A25: 7067900985 | B25: Enugu | C25: Bp tea | D25: 1 | E25: 21/7/2026
A26: 7067900985 | B26: Enugu | C26: Tea for men | D26: 1 | E26: 21/7/2026
A27: 8033343151 | B27: Lagos Idimu | C27: Tea for men | D27: 1 | E27: 21/12/2026
A28: 8136446085 | B28: NNEWI | C28: Prostrate | D28: 1 | E28: 23/7/2026
A29: 9014880117 | B29: Enugu | C29: Ulcer | D29: 1 | E29: 23/1/2026
A30: 8136446085 | B30: NNEWI | C30: Tea for men | D30: 1 | E30: 23/11/2026
B31: Aba | C31: P05/Font | D31: 1 | E31: 23/1/2026
B32: Aba | C32: Tea for men | D32: 1 | E32: 23/1/2026
B33: Lagos | C33: Sperm boost | D33: 1 | E33: 23/11/2026

Sheet Sheet3
A1: Phone number | B1: Destination | C1: Product | D1: Quantity | E1: Date/Dispatcher number
A2: 8034623817 | B2: Lucky World (Lagos) | C2: BP tea | D2: 2 | E2: 25/7/2026
A3: 80463984 | B3: Lucky World Lagos | C3: Ulcer tea | D3: 2 | E3: 25/7/2026
A4: 803254229 | B4: Awka | C4: Lungs tea | D4: 1 | E4: 25/7/2026
A5: +1(214)7233147 | B5: USA | C5: tea for men | D5: 2 | E5: 26/7/2026
A6: 8135846163 | B6: Awka | C6: small kettle | D6: 2 | E6: 26/7/2026
A7: 7046822557 | B7: Asaba | C7: Binel | D7: 1 | E7: 26/7/2026
A8: 7046822557 | B8: Asaba | C8: Solar generator | D8: 1 | E8: 26/7/2026
A9: 8035846163 | B9: Awka | C9: Cholesterol Tea | D9: 2 | E9: 26/7/2026
B10: Umuahia | C10: Liver Tea | D10: 2 | E10: 26/7/2026
A11: 9037349461 | B11: Bayelsa | C11: Kidney | D11: 2 | E11: 27/7/2026
A12: 8035655076 | B12: Abuja Gwarinpa | C12: Ulcer tea | D12: 3 | E12: 27/7/2026
A13: 8035655076 | B13: Abuja Kubwa | C13: Pie Cream | D13: 1 | E13: 28/7/2026
A14: 8034240881 | B14: Lagos Mile12 | C14: Cholesterol | D14: 1 | E14: 29/7/2026
A15: 8034363923 | B15: Onitsha | C15: Ulcer Tea | D15: 2 | E15: 27/7/2026
A16: 7071237348 | B16: Umuahia | C16: Ulcer Tea | D16: 2 | E16: 46030
A17: 8163838250 | B17: Umuahia | C17: Ulcer Tea | D17: 1 | E17: 46030
A18: 9036852785 | B18: Umuahia | C18: Fibroid | D18: 1 | E18: 46089
A19: 8063088411 | B19: Lagos Iyanapaja | C19: Cataract tea | D19: 2 | E19: 46089
A20: 9024852188 | B20: Lagos | C20: Pains tea | D20: 1 | E20: 46150
A21: 9024852188 | B21: Lagos | C21: ulcer Tea | D21: 1 | E21: 46150
A22: 9024852188 | B22: Lagos | C22: Immune System | D22: 1 | E22: 46150
A23: 9161382849 | B23: Warri | C23: Ulcer tea | D23: 1 | E23: 46150
A24: 8163854758 | B24: Umuahia | C24: Infection Tea | D24: 1 | E24: 46181
A25: 7039718944 | B25: Lagos Main | C25: Immune Tea | D25: 1 | E25: 46181
A26: 7039718944 | B26: Lagos main | C26: Cholesterol tea | D26: 1 | E26: 46181
A27: 7039718944 | B27: Lagos main | C27: ulcer | D27: 1 | E27: 46181
A28: 8034863417 | B28: Aba | C28: Sugar | D28: 1 | E28: 46181
C29: Slimming | D29: 4 | E29: 46211
C30: Sugar | D30: 4 | E30: 46211
C31: Infection | D31: 2 | E31: 46061
A32: 8035131868 | B32: Minna | C32: Sperm booster | D32: 1 | E32: 46061
A33: 8035131868 | B33: Aba | C33: Tea for men | D33: 1

Sheet Sheet4
A1: Phone Number | B1: Destination | C1: Products | D1: Quantity | E1: Dispatch Date
A2: 8036205454 | B2: Benin City | C2: Sugar Tea | D2: 1 | E2: 46362
A3: 8036205454 | B3: Benin City | C3: Catarrak Tea | D3: 1 | E3: 46362
A4: 8036205454 | B4: Benin City | C4: Slimming Tea | D4: 1 | E4: 46362
A5: 8036205454 | B5: Benin City | C5: Cholesterol Tea | D5: 1 | E5: 46362
A6: 8033914922 | B6: Ikeja, Lagos | C6: Testosterone | D6: 1 | E6: 18/6/2026
A7: 8164386288 | B7: ABA, Onyerachi | C7: Infection Tea | D7: 1 | E7: 18/6/2026
A8: 8067563481 | B8: Ezeore, Ondo | C8: Sugar Tea | D8: 3 | E8: 18/6/2026
A9: 8039361062 | B9: Port harcourt | C9: Sugar Tea | D9: 1 | E9: 18/6/2026
A10: 8033914922 | B10: Ikeja, Lagos | C10: Infection Tea | D10: 1 | E10: 18/6/2026
A11: 9031212133 | B11: Abuja | C11: Slimming Tea | D11: 2 | E11: 18/6/2026
A12: 8037262183 | B12: Abuja | C12: Arthritis Tea | D12: 1 | E12: 18/6/2026
A13: 9040570411 | B13: Port harcourt | C13: Kidney Tea | D13: 1 | E13: 19/6/2026
A14: 9070520411 | B14: Port harcourt | C14: Liver Tea | D14: 1 | E14: 19/6/2026
A15: 8037329451 | B15: Bayelsa | C15: Postrate Tea | D15: 2 | E15: 19/6/2026
A16: 7054883458 | B16: Anambra / Nnewi | C16: Fibroid Tea | D16: 1 | E16: 19/6/2026
A17: 8025088942 | B17: Lagos, Agege | C17: Ulcer Tea | D17: 1 | E17: 19/6/2026
... A33: 8036709982 | B33: Abuja, Gwagwalada | C33: Sugar Tea | D33: 1 | E33: 23/6/2026

Sheet Sheet7
A1: Phone Number | B1: Destination | C1: Products | D1: Quantity | E1: Dispatch Date
A2: 8137427436 | B2: Lagos | C2: Ulcer Tea | D2: 1 | E2: 46272
A3: 8069128133 | B3: Lagos | C3: Clipper | D3: 1 | E3: 46272
A4: 9137235655 | B4: Umuahia | C4: Sugar Tea | D4: 2 | E4: 46272
A5: 9137235655 | B5: Umuahia | C5: Infection Tea | D5: 2 | E5: 46272
A6: 9137235655 | B6: Umuahia | C6: Infection Tea | D6: 1 | E6: 46272
A7: 8038479838 | B7: Abuja | C7: Pile Tea | D7: 1 | E7: 46302
A8: 8038479838 | B8: Abuja | C8: Slimming Tea | D8: 2 | E8: 46302
A9: 8038479838 | B9: Abuja | C9: Ulcer | D9: 1 | E9: 46363
A10: 8068219822 | B10: Onitsha | C10: Bladder Tea | D10: 1 | E10: 46363
A11: 8038921564 | B11: Aba | C11: Tea for men | D11: 1 | E11: 46363
A12: 8038921564 | B12: Aba | C12: Ulcer Tea | D12: 1 | E12: 14/7/2026
A13: 8038921564 | B13: Aba | C13: Ulcer Tea | D13: 1 | E13: 14/7/2026
A14: 8107434150 | B14: Nnewi | C14: Tea for men | D14: 2 | E14: 14/7/2026
A15: 8107434150 | B15: Nnewi | C15: Sugar | D15: 1 | E15: 14/7/2026
A16: 8107434150 | B16: Nnewi | C16: Sperm Booster | D16: 1 | E16: 14/7/2026
A17: 8069127003 | B17: Zubru | C17: Sugar Tea | D17: 2 | E17: 14/7/2026
A18: 8032379882 | B18: Asaba | C18: Infection Tea | D18: 1 | E18: 14/7/2026
A19: 8095438453 | B19: Aba | C19: Antibiotic | D19: 2 | E19: 14/7/2026
A20: 8095438453 | B20: Aba | C20: BP | D20: 2 | E20: 14/7/2026
A21: 8095438453 | B21: Aba | C21: Car Airfresher | D21: 1 | E21: 14/7/2026
A22: 8039315785 | B22: Nnewi | C22: Slimming | D22: 1 | E22: 14/7/2026
A23: 8039315785 | B23: Nnewi | C23: Tea for men | D23: 1 | E23: 14/7/2026
... A32: 9074430301 | B32: Aba | C32: Sperm Booster | D32: 1 | E32: 15/7/2026

Sheet SALES REPORT
A1: DATE | B1: Customer ID | C1: Phone Number | D1: City | E1: State | F1: Product | G1: Quantity
A2: 46185 | B2: 1001 | C2: 08036205454 | D2: Benin | E2: Benin | F2: Sugar Tea | G2: 1
A3: 46185 | B3: 1001 | C3: 08036205454 | D3: Benin | E3: Benin | F3: Cataract tea | G3: 1
A4: 46185 | B4: 1001 | C4: 08036205454 | D4: Benin | E4: Benin | F4: Slimming Tea | G4: 1
A5: 46185 | B5: 1001 | C5: 08036205454 | D5: Benin | E5: Benin | F5: Cholestrol Tea | G5: 1
A6: 46191 | B6: 1002 | C6: 08164386288 | D6: Aba | E6: Abia | F6: Infection Tea | G6: 1
A7: 46191 | B7: 1003 | C7: 09031212133 | D7: Abuja | E7: Abuja | F7: Slimming Tea | G7: 2
A8: 46191 | B8: 1004 | C8: 08037262183 | D8: Abuja | E8: Abuja | F8: Arthritis Tea | G8: 1
A9: 46191 | B9: 1005 | C9: 08067563481 | D9: Ezeore | E9: Ondo | F9: Sugar Tea | G9: 3
A10: 46191 | B10: 1006 | C10: 08033914927 | D10: Ikeja | E10: Lagos | F10: Infection Tea | G10: 1
A11: 46191 | B11: 1006 | C11: 08033914927 | D11: Ikeja | E11: Lagos | F11: Infection Tea | G11: 1
A12: 46191 | B12: 1007 | C12: 08039361062 | D12: Portharcourt | E12: Rivers | F12: Sugar Tea | G12: 1
A13: 46192 | B13: 1008 | C13: 07054883458 | D13: Awka | E13: Anambra | F13: Fibroid Tea | G13: 1
... A73: 46209 | B73: 1132 | C73: 08105593152 | D73: Aba | E73: Abia | F73: Sugar Tea | G73: 1
A74: 46209 | B74: 1133 | D74: Akwa Ibom | E74: Uyo | F74: Slimming Tea | G74: 1
A75: 46209 | B75: 1133 | D75: Akwa Ibom | E75: Uyo | F75: Tea For Men | G75: 2
A76: 46209 | B76: 1042 | C76: 07033129893 | D76: Enugu | E76: Enugu | F76: Indigestion Tea | G76: 1
A77: 46209 | B77: 1043 | C77: 07033129894 | D77: Enugu | E77: Enugu | F77: Slimming Tea | G77: 1
A78: 46209 | B78: 1134 | D78: Enugu | E78: Enugu | F78: Infection Tea | G78: 1
A79: 46209 | B79: 1134 | D79: Enugu | E79: Enugu | F79: Fibroid Tea | G79: 1
A80: 46209 | B80: 1134 | D80: Enugu | E80: Enugu | F80: Bp Tea | G80: 1
A81: 46209 | B81: 1044 | C81: 08063637793 | D81: Umuahia | E81: Abia | F81: Slimming Tea | G81: 2
A82: 46209 | B82: 1044 | C82: 08063637793 | D82: Umuahia | E82: Abia | F82: Sugar Tea | G82: 2
A83: 46210 | B83: 1135 | D83: 151, Agu Junction | E83: Imo | F83: Sugar Tea | G83: 1
A84: 46210 | B84: 1045 | C84: 07034731166 | D84: Aba | E84: Abia | F84: Prostrate Tea | G84: 2
A85: 46210 | B85: 1136 | C85: 08069155175 | D85: Aba | E85: Abia | F85: Solar Generator | G85: 1
A86: 46210 | B86: 1136 | C86: 08069155175 | D86: Aba | E86: Abia | F86: Lavender Skin | G86: 1
A87: 46210 | B87: 1046 | C87: 08032587950 | D87: Abuja | E87: Abuja | F87: Prostrate Tea | G87: 1
A88: 46210 | B88: 1047 | C88: N/a | D88: Akwa Ibom | E88: Uyo | F88: Sugar Tea | G88: 1
A89: 46210 | B89: 1048 | C89: 08060681137 | D89: Enugu | E89: Enugu | F89: Tea For Men | G89: 1
A90: 46210 | B90: 1049 | C90: 08141362251 | D90: Lagos | E90: Lagos | F90: Sperm Booster | G90: 1
A91: 46210 | B91: 1050 | C91: 0704458442 | D91: Portharcourt | E91: Rivers | F91: Liver Tea | G91: 1
A92: 46211 | B92: 1051 | C92: 08034047224 | D92: Aba | E92: Abia | F92: Small Blender | G92: 1
A93: 46211 | B93: 1052 | C93: 09169449197 | D93: Awka | E93: Anambra | F93: Small Blender | G93: 1
A94: 46211 | B94: 1053 | C94: 07044817710 | D94: Portharcourt | E94: Rivers | F94: Prostrate Tea | G94: 1
A95: 46211 | B95: 1054 | C95: 08063002287 | D95: Portharcourt | E95: Rivers | F95: Cholestrol Tea | G95: 3
... A128: 46218 | B128: 1074 | C128: 07026726707, 07026726204 | D128: Malasolu | E128: Lagos | F128: Tea For Men | G128: 2
A129: 46218 | B129: 1144 | D129: Malasolu | E129: Lagos | F129: Infection Tea | G129: 1
A130: 46218 | B130: 1075 | C130: 08146868132 | D130: Nsukka | E130: Enugu | F130: Sugar Tea | G130: 1
A131: 46218 | B131: 1137 | D131: Orlu | E131: Imo | F131: Ulcer Tea | G131: 2
...

Sheet chart
A1: ;;
A2: ]
A5: state | B5: orders | C5: by percentage
A6: {=UNIQUE(Table1[State])} -> Benin | B6: 7 | C6: 0.023333333
A7: Abia | B7: 72 | C7: 0.24
A8: Abuja | B8: 16 | C8: 0.053333333
A9: Ondo | B9: 1 | C9: 0.0033333333
A10: Lagos | B10: 81 | C10: 0.27
A11: Rivers | B11: 16 | C11: 0.053333333
A12: Anambra | B12: 49 | C12: 0.16333333
A13: Bayelsa | B13: 3 | C13: 0.01
A14: Uyo | B14: 6 | C14: 0.02
A15: Borno | B15: 2 | C15: 0.0066666667
A16: Ebonyi | B16: 1 | C16: 0.0033333333
A17: N/a | B17: 5 | C17: 0.016666667
A18: Enugu | B18: 33 | C18: 0.11
... A21: Delta | B21: 10 | C21: 0.033333333
A27: product performance
A29: Sugar Tea | B29: 37
A30: Cataract tea | B30: 36
A31: Slimming Tea | B31: 21
A32: Cholestrol Tea | B32: 19
A33: Infection Tea | B33: 17
A34: Arthritis Tea | B34: 15
A35: Prostrate Tea | B35: 13
A36: Ulcer Tea | B36: 13
A37: Kidney Tea | B37: 11
A38: Liver Tea | B38: 10
A39: Tea For Men | B39: 6
A40: Bp Tea | B40: 5
... A71: Tea For Bp | B71: 1
A76: FIRST TEN CUSTOMERS
A77: Customer | B77: Orders
A78: 1103 | B78: 10
A79: 1016 | B79: 8
A80: 1128 | B80: 8
A81: 1112 | B81: 7
A82: 1007 | B82: 6
A83: 1020 | B83: 6
A84: 1027 | B84: 6
...

Sheet Sheet9
A1: Phone Number | B1: Destination | C1: Product | D1: Quantity | E1: Dispatch Date
A2: 8034621041 | B2: Lucky David Lagos | C2: BP Tea | D2: 2 | E2: 25/7/2026
A3: 8034621041 | B3: Lucky David Lagos | C3: ulcer tea | D3: 2 | E3: 25/7/2026
A4: 8032584227 | B4: Asaba | C4: lugs tea | D4: 1 | E4: 25/7/2026
A5: +1(214)723314 | B5: USA | C5: Tea for men | D5: 2 | E5: 26/7/2026
A6: 8035846113 | B6: Awka | C6: small kettle | D6: 2 | E6: 26/7/2026
A7: 7046822541 | B7: Asaba | C7: Panel | D7: 1 | E7: 26/7/2026
A8: 7046822541 | B8: Asaba | C8: Solar generator | D8: 1 | E8: 26/7/2026
A9: 8035846113 | B9: Awka | C9: Cholesterol Tea | D9: 2 | E9: 26/7/2026
A10: 8037349461 | B10: Umuahia | C10: Liver Tea | D10: 1 | E10: 26/7/2026
A11: 8035655076 | B11: Bayelsa | C11: Kidney | D11: 2 | E11: 27/7/2026
A12: 8035655076 | B12: Abuja Lugbe | C12: Ulcer Tea | D12: 3 | E12: 27/7/2026
A13: 8034240881 | B13: Abuja Kubwa | C13: Pie Cream | D13: 1 | E13: 28/7/2026
A14: 8034363923 | B14: Lagos Mazamaza | C14: Cholesterol | D14: 1 | E14: 29/7/2026
A15: 7071257348 | B15: Onitsha | C15: Ulcer Tea | D15: 2 | E15: 29/7/2026
A16: 8163852785 | B16: Umuahia | C16: Ulcer Tea | D16: 2 | E16: 46030
A17: 9036852785 | B17: Umuahia | C17: Ulcer Tea | D17: 1 | E17: 46030
A18: 8063088411 | B18: Umuahia | C18: Fibroid | D18: 1 | E18: 46089
A19: 7024852188 | B19: Lagos iyanapaja | C19: Cataract tea | D19: 2 | E19: 46089
A20: 7024852188 | B20: Lagos | C20: Prost Tea | D20: 1 | E20: 46150
A21: 7024852188 | B21: Lagos | C21: ulcer tea | D21: 1 | E21: 46150
A22: 9161382849 | B22: Lagos | C22: Immune system | D22: 1 | E22: 46150
A23: 8163854753 | B23: Warri | C23: Ulcer Tea | D23: 1 | E23: 46181
A24: 7039718944 | B24: Umuahia | C24: Infection Tea | D24: 1 | E24: 46181
A25: 7039718944 | B25: LAGOS maza | C25: Immune tea | D25: 1 | E25: 46181
A26: 7039718944 | B26: Lagos mazamaza | C26: Cholesterol tea | D26: 1 | E26: 46181
A27: 8034863417 | B27: Lagos maza | C27: ulcer | D27: 1 | E27: 46181
B28: Aba | C28: Sugar | D28: 1 | E28: 46273
C29: Slimming | D29: 4 | E29: 46334
A30: 8036512868 | C30: Sugar | D30: 4 | E30: 46334
A31: 8036512868 | B31: Aba | C31: Infection
A32: 8036512868 | B32: Aba | C32: Spermbooster
B33: Aba | C33: Tea for men | D33: 1

Sheet Sheet8
A1: Phone Number | B1: Address/Location | C1: Product | D1: Quantity/Duration | E1: Date
A2: 7030910093 | B2: Enugu | C2: Infection | D2: 1 | E2: 46303
A3: 8030910093 | B3: Enugu | C3: Ulcer Tea | D3: 1 | E3: 46303
A4: 7029852101 | B4: Lagos | C4: Lung | D4: 1 | E4: 46303
A5: 7029852101 | B5: Abuja | C5: Sugar | D5: 2 | E5: 46334
A6: 7034450433 | B6: Enugu | C6: Slimming | D6: 1 | E6: 46334
A7: " | B7: Anka | C7: Piles | D7: 2 | E7: 46334
A8: " | B8: Anka | C8: Piles | D8: 2 | E8: 46334
A9: 8034213214 | B9: Aba | C9: Ulcer | D9: 1 | E9: 46364
A10: 8163854758 | B10: Umuahia | C10: Cholesterol | D10: 1 | E10: 46364
A11: 806672050 | B11: Asaba | C11: Infection + Slim | D11: 1 | E11: 46364
A12: 8163854758 | B12: Umuahia | C12: Liver Tea | D12: 1 | E12: 46364
A13: 8163854758 | B13: Umuahia | C13: Slimming + Tea | D13: 1 | E13: 46364
A14: 7080910093 | B14: Enugu | C14: Infection + Tea | D14: 1 | E14: 46364
A15: 7030910093 | B15: Enugu | C15: Immune booster | D15: 1 | E15: 46364
A16: 7036363536 | B16: Lagos, Festac | C16: Copper | D16: 1 | E16: 46364
A17: 8032151901 | B17: Lagos Estate | C17: Slimming Tea | D17: 1 | E17: 13/8/2026
A18: 8032151901 | B18: Lagos Estate | C18: BP + Tea | D18: 1 | E18: 13/8/2026
A19: 8032151901 | B19: Lagos Estate | C19: Sperm Booster | D19: 1 | E19: 15/8/2026
A20: 9034606524 | B20: Aba, Abia State | C20: Infection Tea | D20: 2 | E20: 17/8/2026
A21: 8065538794 | B21: Iyamho, Lagos | C21: B.p. Tea | D21: 2 | E21: 17/8/2026
A22: 8033238943 | B22: Mushin, Lagos | C22: Ulcer Tea | D22: 1 | E22: 17/8/2026
A23: 8163854758 | B23: Umuahia, Abia state | C23: Tea for Men | D23: 1 Sachet | E23: 20/8/2026
A24: 8163854758 | B24: " | C24: Ulcer Tea | D24: 1 Sachet | E24: 20/8/2026
A25: " | B25: " | C25: Cholesterol Tea | D25: 1 Sachet | E25: 20/8/2026
A26: 9034606524 | B26: Aba, Abia state | C26: Infection Tea | D26: 1 Sachet | E26: 24/8/2026
A27: " | B27: " | C27: Sperm Booster | D27: 1 Tin | E27: 24/8/2026
A28: " | B28: " | C28: Tea for Men | D28: 1 Sachet | E28: 24/8/2026
A29: 8032151901 | B29: Lagos | C29: Prostate Tea | D29: 1 sachet | E29: 24/8/2026
A30: " | B30: " | C30: B.p. Tea | D30: 1 sachet | E30: 24/8/2026
A31: " | B31: " | C31: Ulcer Tea | D31: 1 sachet | E31: 24/8/2026
A32: 8163005469 | B32: Lagos | C32: Tea for Kidney | D32: 1 Tin | E32: 24/8/2026
A33: 8064995955 | B33: Ajah, Lagos | C33: Tea for Liver | D33: 1 sachet | E33: 24/8/2026

Sheet Sheet10
A1: Date | B1: Customer ID | C1: Phone Number | D1: Destination | E1: State | F1: Product | G1: Quantity
A2: 46259 | C2: 09121633167 | D2: Abuja | E2: Lagos | F2: 3.5Kva Solar Generator | G2: 1
A3: 46260 | C3: 08035619487 | D3: Umuahia | E3: Abia | F3: Ulcer Tea | G3: 2
A4: 46260 | C4: 08037620132 | D4: Enugu | E4: Enugu | F4: Sugar Tea | G4: 1
A5: 46260 | C5: 08037620132 | D5: Enugu | E5: Enugu | F5: Cholesterol Tea | G5: 1
A6: 46260 | C6: 08038499525 | D6: Abuja | E6: Abuja | F6: 3 Kva Gen | G6: 1
A7: 46261 | C7: 08077490122 | D7: Aba | E7: Abia | F7: 3 Lens Camera | G7: 1
A8: 46261 | C8: 08077490122 | D8: Aba | E8: Abia | F8: Solar Charger (4G) | G8: 1
A9: 46261 | C9: 08140942884 | D9: Aba | E9: Abia | F9: Desktop Fan | G9: 1
A10: 46262 | C10: 08140942884 | D10: Aba | E10: Abia | F10: Desktop Fan | G10: 1
A11: 46265 | C11: 08053719072 | D11: Mazamaza | E11: Lagos | F11: Infection Tea | G11: 1
A12: 46265 | C12: 08053719072 | D12: Mazamaza | E12: Lagos | F12: Tea For Kidney | G12: 1
A13: 46265 | C13: 09065620512 | D13: Mazamaza | E13: Lagos | F13: Tea For Bp | G13: 2
... A23: 46268 | C23: 08119854427 | D23: Enugu | E23: Enugu | F23: Tea For Men | G23: 2
A24: 46269 | C24: 09045753713 | D24: Yalualua | F24: B.P Tea | G24: 6
A25: 46269 | C25: 09045753713 | D25: Yalualua | F25: Sugar Tea | G25: 1
A26: 46269 | C26: 09045753713 | D26: Yalualua | F26: Ulcer Tea | G26: 1
A27: 46269 | C27: 09045753713 | D27: Yalualua | F27: Tea For Men | G27: 1
A28: 46269 | C28: 08036679485 | D28: Onitsha | E28: Anambra | F28: Ulcer Tea | G28: 1
A29: 46269 | C29: 08036679485 | D29: Onitsha | E29: Anambra | F29: Sugar Tea | G29: 2
A30: 46270 | C30: 08035769601 | D30: Nnewi | E30: Anambra | F30: Ulcer Tea | G30: 1
A31: 46270 | C31: 08035769601 | D31: Nnewi | E31: Anambra | F31: Kidney Tea | G31: 1
A32: 46270 | C32: 08035769601 | D32: Nnewi | E32: Anambra | F32: Love Tea | G32: 1

Sheet customer contact
A3: {=UNIQUE('SALES REPORT'!C2:C238)} -> 08036205454 | B3: 1001
A4: 08164386288 | B4: 1002
A5: 09031212133 | B5: 1003 | F5: Sugar Tea
A6: 08037262183 | B6: 1004 | F6: Cataract tea
A7: 08067563481 | B7: 1005 | F7: Slimming Tea
A8: 08033914927 | B8: 1006 | F8: Cholestrol Tea
A9: 08039361062 | B9: 1007 | F9: Infection Tea
A10: 07054883458 | B10: 1008 | F10: Arthritis Tea
A11: 08037329451 | B11: 1009 | F11: Fibroid Tea
A12: 08025088942 | B12: 1010 | F12: Prostrate Tea
A13: 09040570411 | B13: 1011 | F13: Ulcer Tea
A14: 09070520411 | B14: 1012 | F14: Kidney Tea
A15: 07033720253 | B15: 1013 | F15: Liver Tea
A16: 08030828539 | B16: 1014 | F16: Tea For Men
... A48: 08105593152 | B48: 1041 | F48: Tea For Bp
B49: 1042
A50: 07033129893 | B50: 1043
A51: 07033129894 | B51: 1044
A52: 08063637793 | B52: 1045
A53: 07034731166 | B53: 1046
A54: 08032587950 | B54: 1047
A55: N/a | B55: 1048
A56: 08060681137 | B56: 1049
A57: 08141362251 | B57: 1050
A58: 0704458442 | B58: 1051
A59: 08034047224 | B59: 1052
A60: 09169449197 | B60: 1053
A61: 07044817710 | B61: 1054
... A136: 09065620512 | B136: 1129

Sheet Sheet16
A3: Total sales | C3: Total customers | E3: Total orders
A4: =SUM('SALES REPORT'!G2:G1000) -> 329 | C4: {=COUNTA(UNIQUE('SALES REPORT'!B2:B1000))} -> 144 | E4: 237
C8: SALES PERFORMANCE DASHBOARD
I11: HIGHEST PERFORMING STATE
I13: {=INDEX('ED ANALYSIS'!J3:J19,MATCH(MAX('ED ANALYSIS'!L3:L19),'ED ANALYSIS'!L3:L19,0))} -> Lagos

Sheet ED ANALYSIS
A2: QUESTIONS | J2: State performance according to orders | N2: product performance | Q2: State performance by customer conversion
J3: state | K3: orders | L3: by percentage
J4: {=UNIQUE(Table1[State])} -> Benin | K4: 7 | L4: 0.023333333 | N4: Sugar Tea | O4: 37
A5: which state has the highest performance by percentage | J5: Abia | K5: 72 | L5: 0.24 | N5: Cataract tea | O5: 36
A6: customer with the highest order | J6: Abuja | K6: 16 | L6: 0.053333333 | N6: Slimming Tea | O6: 21
A7: top ten customers | J7: Ondo | K7: 1 | L7: 0.0033333333 | N7: Cholestrol Tea | O7: 19
J8: Lagos | K8: 81 | L8: 0.27 | N8: Infection Tea | O8: 17
A9: product with the most sells | J9: Rivers | K9: 16 | L9: 0.053333333 | N9: Arthritis Tea | O9: 15
A10: product performance in states | J10: Anambra | K10: 49 | L10: 0.16333333 | N10: Prostrate Tea | O10: 13
J11: Bayelsa | K11: 3 | L11: 0.01 | N11: Ulcer Tea | O11: 13
J12: Uyo | K12: 6 | L12: 0.02 | N12: Kidney Tea | O12: 11
J13: Borno | K13: 2 | L13: 0.0066666667 | N13: Liver Tea | O13: 10
A14: PRODUCT | J14: Ebonyi | K14: 1 | L14: 0.0033333333 | N14: Tea For Men | O14: 6
A15: Sugar Tea | J15: N/a | K15: 5 | L15: 0.016666667 | N15: Bp Tea | O15: 5
A16: Cataract tea | J16: Enugu | K16: 33 | L16: 0.11 | N16: Power Bank | O16: 4
A17: Slimming Tea | J17: Usa | K17: 4 | L17: 0.013333333 | N17: Solar Generator | O17: 4
A18: Cholestrol Tea | J18: Imo | K18: 4 | L18: 0.013333333 | N18: Pillow | O18: 3
A19: Infection Tea | J19: Delta | K19: 10 | L19: 0.033333333 | N19: Sperm Booster | O19: 3
A20: Arthritis Tea | N20: Indigestion Tea | O20: 3
A21: Fibroid Tea | N21: Solar Generator small | O21: 2
A22: Prostrate Tea | J22: Customer | K22: Orders | N22: Lavender Skin | O22: 2
A23: Ulcer Tea | G23: FIRST TEN CUSTOMERS | J23: 1103 | K23: 10 | N23: Small Blender | O23: 2
A24: Kidney Tea | D24: Customer id | E24: ORDERS | G24: Customer | H24: Orders | J24: 1016 | K24: 8 | N24: Clipper | O24: 2
A25: Liver Tea | D25: 1103 | E25: 10 | G25: 1103 | H25: 10 | J25: 1128 | K25: 8 | N25: Pile Tea | O25: 1
A26: Tea For Men | D26: 1016 | E26: 8 | G26: 1016 | H26: 8 | J26: 1112 | K26: 7 | N26: Bladder Tea | O26: 1
A27: Bp Tea | D27: 1128 | E27: 8 | G27: 1128 | H27: 8 | J27: 1007 | K27: 6 | N27: Anti aging Tea | O27: 1
A28: Power Bank | G28: 1112 | H28: 7 | J28: 1020 | K28: 6 | N28: Bp tea | O28: 1
A29: Solar Generator | G29: 1007 | H29: 6 | J29: 1027 | K29: 6 | N29: Car Airfresher | O29: 1
A30: Pillow | G30: 1020 | H30: 6 | J30: 1032 | K30: 6 | N30: Infertility Tea | O30: 1
A31: Sperm Booster | G31: 1027 | H31: 6 | J31: 1054 | K31: 5 | N31: Light | O31: 1
A32: Indigestion Tea | G32: 1032 | H32: 6 | J32: 1057 | K32: 5 | N32: Juice Extractor | O32: 1
A33: Solar Generator small | G33: 1054 | H33: 5 | J33: 1061 | K33: 5 | N33: Lungs Tea | O33: 1
A34: Lavender Skin | G34: 1057 | H34: 5 | J34: 1082 | K34: 5 | N34: Solar Panel | O34: 1
A35: Small Blender | J35: 1105 | K35: 5 | N35: Small Kettle | O35: 1
A36: Clipper | J36: 1130 | K36: 5 | N36: Pile Cream | O36: 1
A37: Pile Tea | J37: 1001 | K37: 4 | N37: Cataract Tea | O37: 1
A38: Bladder Tea | J38: 1028 | K38: 4 | N38: Immune booster | O38: 1
A39: Anti aging Tea | J39: 1030 | K39: 4 | N39: 3.5Kva Solar Generator | O39: 1
A40: Bp tea | J40: 1034 | K40: 4 | N40: Cholesterol Tea | O40: 1
A41: Car Airfresher | J41: 1044 | K41: 4 | N41: 3 Kva Gen | O41: 1
...

Sheet Sheet14
C4: Benin | D4: Abia | E4: Abuja | F4: Ondo | G4: Lagos | H4: Rivers | I4: Anambra | J4: Bayelsa | K4: Uyo | L4: Borno | M4: Ebonyi | N4: N/a | O4: Enugu | P4: Usa | Q4: Imo | R4: Delta
B5: Sugar Tea | C5: =SUMIFS('SALES REPORT'!$G$2:$G1000,'SALES REPORT'!$E$2:$E1000,C$4,'SALES REPORT'!$F$2:$F1000,$B5) -> 1 | D5: =SUMIFS('SALES REPORT'!$G$2:$G1000,'SALES REPORT'!$E$2:$E1000,D$4,'SALES REPORT'!$F$2:$F1000,$B5) -> 11 | E5: =SUMIFS('SALES REPORT'!$G$2:$G1000,'SALES REPORT'!$E$2:$E1000,E$4,'SALES REPORT'!$F$2:$F1000,$B5) -> 3 | F5: =SUMIFS('SALES REPORT'!$G$2:$G1000,'SALES REPORT'!$E$2:$E1000,F$4,'SALES REPORT'!$F$2:$F1000,$B5) -> 3 | G5: =SUMIFS('SALES REPORT'!$G$2:$G1000,'SALES REPORT'!$E$2:$E1000,G$4,'SALES REPORT'!$F$2:$F1000,$B5) -> 10 | H5: =SUMIFS('SALES REPORT'!$G$2:$G1000,'SALES REPORT'!$E$2:$E1000,H$4,'SALES REPORT'!$F$2:$F1000,$B5) -> 2 | I5: =SUMIFS('SALES REPORT'!$G$2:$G1000,'SALES REPORT'!$E$2:$E1000,I$4,'SALES REPORT'!$F$2:$F1000,$B5) -> 2 | J5: =SUMIFS('SALES REPORT'!$G$2:$G1000,'SALES REPORT'!$E$2:$E1000,J$4,'SALES REPORT'!$F$2:$F1000,$B5) -> 0 | ... R5: =SUMIFS('SALES REPORT'!$G$2:$G1000,'SALES REPORT'!$E$2:$E1000,R$4,'SALES REPORT'!$F$2:$F1000,$B5) -> 2
B6: Cataract tea | C6: =SUMIFS('SALES REPORT'!$G$2:$G1000,'SALES REPORT'!$E$2:$E1000,C$4,'SALES REPORT'!$F$2:$F1000,$B6) -> 1 | D6: =SUMIFS('SALES REPORT'!$G$2:$G1000,'SALES REPORT'!$E$2:$E1000,D$4,'SALES REPORT'!$F$2:$F1000,$B6) -> 0 | E6: =SUMIFS('SALES REPORT'!$G$2:$G1000,'SALES REPORT'!$E$2:$E1000,E$4,'SALES REPORT'!$F$2:$F1000,$B6) -> 0 | F6: =SUMIFS('SALES REPORT'!$G$2:$G1000,'SALES REPORT'!$E$2:$E1000,F$4,'SALES REPORT'!$F$2:$F1000,$B6) -> 0 | G6: =SUMIFS('SALES REPORT'!$G$2:$G1000,'SALES REPORT'!$E$2:$E1000,G$4,'SALES REPORT'!$F$2:$F1000,$B6) -> 2 | H6: =SUMIFS('SALES REPORT'!$G$2:$G1000,'SALES REPORT'!$E$2:$E1000,H$4,'SALES REPORT'!$F$2:$F1000,$B6) -> 0 | I6: =SUMIFS('SALES REPORT'!$G$2:$G1000,'SALES REPORT'!$E$2:$E1000,I$4,'SALES REPORT'!$F$2:$F1000,$B6) -> 0 | J6: =SUMIFS('SALES REPORT'!$G$2:$G1000,'SALES REPORT'!$E$2:$E1000,J$4,'SALES REPORT'!$F$2:$F1000,$B6) -> 0 | ... R6: =SUMIFS('SALES REPORT'!$G$2:$G1000,'SALES REPORT'!$E$2:$E1000,R$4,'SALES REPORT'!$F$2:$F1000,$B6) -> 1
B7: Slimming Tea | C7: =SUMIFS('SALES REPORT'!$G$2:$G1000,'SALES REPORT'!$E$2:$E1000,C$4,'SALES REPORT'!$F$2:$F1000,$B7) -> 1 | D7: =SUMIFS('SALES REPORT'!$G$2:$G1000,'SALES REPORT'!$E$2:$E1000,D$4,'SALES REPORT'!$F$2:$F1000,$B7) -> 6 | E7: =SUMIFS('SALES REPORT'!$G$2:$G1000,'SALES REPORT'!$E$2:$E1000,E$4,'SALES REPORT'!$F$2:$F1000,$B7) -> 4 | F7: =SUMIFS('SALES REPORT'!$G$2:$G1000,'SALES REPORT'!$E$2:$E1000,F$4,'SALES REPORT'!$F$2:$F1000,$B7) -> 0 | G7: =SUMIFS('SALES REPORT'!$G$2:$G1000,'SALES REPORT'!$E$2:$E1000,G$4,'SALES REPORT'!$F$2:$F1000,$B7) -> 5 | H7: =SUMIFS('SALES REPORT'!$G$2:$G1000,'SALES REPORT'!$E$2:$E1000,H$4,'SALES REPORT'!$F$2:$F1000,$B7) -> 1 | I7: =SUMIFS('SALES REPORT'!$G$2:$G1000,'SALES REPORT'!$E$2:$E1000,I$4,'SALES REPORT'!$F$2:$F1000,$B7) -> 4 | J7: =SUMIFS('SALES REPORT'!$G$2:$G1000,'SALES REPORT'!$E$2:$E1000,J$4,'SALES REPORT'!$F$2:$F1000,$B7) -> 0 | ... R7: =SUMIFS('SALES REPORT'!$G$2:$G1000,'SALES REPORT'!$E$2:$E1000,R$4,'SALES REPORT'!$F$2:$F1000,$B7) -> 1
B8: Cholestrol Tea | C8: =SUMIFS('SALES REPORT'!$G$2:$G1000,'SALES REPORT'!$E$2:$E1000,C$4,'SALES REPORT'!$F$2:$F1000,$B8) -> 1 | D8: =SUMIFS('SALES REPORT'!$G$2:$G1000,'SALES REPORT'!$E$2:$E1000,D$4,'SALES REPORT'!$F$2:$F1000,$B8) -> 1 | E8: =SUMIFS('SALES REPORT'!$G$2:$G1000,'SALES REPORT'!$E$2:$E1000,E$4,'SALES REPORT'!$F$2:$F1000,$B8) -> 0 | F8: =SUMIFS('SALES REPORT'!$G$2:$G1000,'SALES REPORT'!$E$2:$E1000,F$4,'SALES REPORT'!$F$2:$F1000,$B8) -> 0 | G8: =SUMIFS('SALES REPORT'!$G$2:$G1000,'SALES REPORT'!$E$2:$E1000,G$4,'SALES REPORT'!$F$2:$F1000,$B8) -> 2 | H8: =SUMIFS('SALES REPORT'!$G$2:$G1000,'SALES REPORT'!$E$2:$E1000,H$4,'SALES REPORT'!$F$2:$F1000,$B8) -> 3 | I8: =SUMIFS('SALES REPORT'!$G$2:$G1000,'SALES REPORT'!$E$2:$E1000,I$4,'SALES REPORT'!$F$2:$F1000,$B8) -> 3 | J8: =SUMIFS('SALES REPORT'!$G$2:$G1000,'SALES REPORT'!$E$2:$E1000,J$4,'SALES REPORT'!$F$2:$F1000,$B8) -> 4 | ... R8: =SUMIFS('SALES REPORT'!$G$2:$G1000,'SALES REPORT'!$E$2:$E1000,R$4,'SALES REPORT'!$F$2:$F1000,$B8) -> 1
B9: Infection Tea | C9: =SUMIFS('SALES REPORT'!$G$2:$G1000,'SALES REPORT'!$E$2:$E1000,C$4,'SALES REPORT'!$F$2:$F1000,$B9) -> 0 | D9: =SUMIFS('SALES REPORT'!$G$2:$G1000,'SALES REPORT'!$E$2:$E1000,D$4,'SALES REPORT'!$F$2:$F1000,$B9) -> 10 | E9: =SUMIFS('SALES REPORT'!$G$2:$G1000,'SALES REPORT'!$E$2:$E1000,E$4,'SALES REPORT'!$F$2:$F1000,$B9) -> 1 | F9: =SUMIFS('SALES REPORT'!$G$2:$G1000,'SALES REPORT'!$E$2:$E1000,F$4,'SALES REPORT'!$F$2:$F1000,$B9) -> 0 | G9: =SUMIFS('SALES REPORT'!$G$2:$G1000,'SALES REPORT'!$E$2:$E1000,G$4,'SALES REPORT'!$F$2:$F1000,$B9) -> 7 | H9: =SUMIFS('SALES REPORT'!$G$2:$G1000,'SALES REPORT'!$E$2:$E1000,H$4,'SALES REPORT'!$F$2:$F1000,$B9) -> 0 | I9: =SUMIFS('SALES REPORT'!$G$2:$G1000,'SALES REPORT'!$E$2:$E1000,I$4,'SALES REPORT'!$F$2:$F1000,$B9) -> 0 | J9: =SUMIFS('SALES REPORT'!$G$2:$G1000,'SALES REPORT'!$E$2:$E1000,J$4,'SALES REPORT'!$F$2:$F1000,$B9) -> 0 | ... R9: =SUMIFS('SALES REPORT'!$G$2:$G1000,'SALES REPORT'!$E$2:$E1000,R$4,'SALES REPORT'!$F$2:$F1000,$B9) -> 1
B10: Arthritis Tea | C10: =SUMIFS('SALES REPORT'!$G$2:$G1000,'SALES REPORT'!$E$2:$E1000,C$4,'SALES REPORT'!$F$2:$F1000,$B10) -> 0 | D10: =SUMIFS('SALES REPORT'!$G$2:$G1000,'SALES REPORT'!$E$2:$E1000,D$4,'SALES REPORT'!$F$2:$F1000,$B10) -> 2 | E10: =SUMIFS('SALES REPORT'!$G$2:$G1000,'SALES REPORT'!$E$2:$E1000,E$4,'SALES REPORT'!$F$2:$F1000,$B10) -> 1 | F10: =SUMIFS('SALES REPORT'!$G$2:$G1000,'SALES REPORT'!$E$2:$E1000,F$4,'SALES REPORT'!$F$2:$F1000,$B10) -> 0 | G10: =SUMIFS('SALES REPORT'!$G$2:$G1000,'SALES REPORT'!$E$2:$E1000,G$4,'SALES REPORT'!$F$2:$F1000,$B10) -> 3 | H10: =SUMIFS('SALES REPORT'!$G$2:$G1000,'SALES REPORT'!$E$2:$E1000,H$4,'SALES REPORT'!$F$2:$F1000,$B10) -> 0 | I10: =SUMIFS('SALES REPORT'!$G$2:$G1000,'SALES REPORT'!$E$2:$E1000,I$4,'SALES REPORT'!$F$2:$F1000,$B10) -> 0 | J10: =SUMIFS('SALES REPORT'!$G$2:$G1000,'SALES REPORT'!$E$2:$E1000,J$4,'SALES REPORT'!$F$2:$F1000,$B10) -> 0 | ... R10: =SUMIFS('SALES REPORT'!$G$2:$G1000,'SALES REPORT'!$E$2:$E1000,R$4,'SALES REPORT'!$F$2:$F1000,$B10) -> 0
B11: Fibroid Tea | C11: =SUMIFS('SALES REPORT'!$G$2:$G1000,'SALES REPORT'!$E$2:$E1000,C$4,'SALES REPORT'!$F$2:$F1000,$B11) -> 0 | D11: =SUMIFS('SALES REPORT'!$G$2:$G1000,'SALES REPORT'!$E$2:$E1000,D$4,'SALES REPORT'!$F$2:$F1000,$B11) -> 1 | E11: =SUMIFS('SALES REPORT'!$G$2:$G1000,'SALES REPORT'!$E$2:$E1000,E$4,'SALES REPORT'!$F$2:$F1000,$B11) -> 0 | F11: =SUMIFS('SALES REPORT'!$G$2:$G1000,'SALES REPORT'!$E$2:$E1000,F$4,'SALES REPORT'!$F$2:$F1000,$B11) -> 0 | G11: =SUMIFS('SALES REPORT'!$G$2:$G1000,'SALES REPORT'!$E$2:$E1000,G$4,'SALES REPORT'!$F$2:$F1000,$B11) -> 0 | H11: =SUMIFS('SALES REPORT'!$G$2:$G1000,'SALES REPORT'!$E$2:$E1000,H$4,'SALES REPORT'!$F$2:$F1000,$B11) -> 0 | I11: =SUMIFS('SALES REPORT'!$G$2:$G1000,'SALES REPORT'!$E$2:$E1000,I$4,'SALES REPORT'!$F$2:$F1000,$B11) -> 1 | J11: =SUMIFS('SALES REPORT'!$G$2:$G1000,'SALES REPORT'!$E$2:$E1000,J$4,'SALES REPORT'!$F$2:$F1000,$B11) -> 0 | ... R11: =SUMIFS('SALES REPORT'!$G$2:$G1000,'SALES REPORT'!$E$2:$E1000,R$4,'SALES REPORT'!$F$2:$F1000,$B11) -> 0
B12: Prostrate Tea | C12: =SUMIFS('SALES REPORT'!$G$2:$G1000,'SALES REPORT'!$E$2:$E1000,C$4,'SALES REPORT'!$F$2:$F1000,$B12) -> 0 | D12: =SUMIFS('SALES REPORT'!$G$2:$G1000,'SALES REPORT'!$E$2:$E1000,D$4,'SALES REPORT'!$F$2:$F1000,$B12) -> 6 | E12: =SUMIFS('SALES REPORT'!$G$2:$G1000,'SALES REPORT'!$E$2:$E1000,E$4,'SALES REPORT'!$F$2:$F1000,$B12) -> 1 | F12: =SUMIFS('SALES REPORT'!$G$2:$G1000,'SALES REPORT'!$E$2:$E1000,F$4,'SALES REPORT'!$F$2:$F1000,$B12) -> 0 | G12: =SUMIFS('SALES REPORT'!$G$2:$G1000,'SALES REPORT'!$E$2:$E1000,G$4,'SALES REPORT'!$F$2:$F1000,$B12) -> 6 | H12: =SUMIFS('SALES REPORT'!$G$2:$G1000,'SALES REPORT'!$E$2:$E1000,H$4,'SALES REPORT'!$F$2:$F1000,$B12) -> 1 | I12: =SUMIFS('SALES REPORT'!$G$2:$G1000,'SALES REPORT'!$E$2:$E1000,I$4,'SALES REPORT'!$F$2:$F1000,$B12) -> 4 | J12: =SUMIFS('SALES REPORT'!$G$2:$G1000,'SALES REPORT'!$E$2:$E1000,J$4,'SALES REPORT'!$F$2:$F1000,$B12) -> 2 | ... R12: =SUMIFS('SALES REPORT'!$G$2:$G1000,'SALES REPORT'!$E$2:$E1000,R$4,'SALES REPORT'!$F$2:$F1000,$B12) -> 0
B13: Ulcer Tea | C13: =SUMIFS('SALES REPORT'!$G$2:$G1000,'SALES REPORT'!$E$2:$E1000,C$4,'SALES REPORT'!$F$2:$F1000,$B13) -> 0 | D13: =SUMIFS('SALES REPORT'!$G$2:$G1000,'SALES REPORT'!$E$2:$E1000,D$4,'SALES REPORT'!$F$2:$F1000,$B13) -> 13 | E13: =SUMIFS('SALES REPORT'!$G$2:$G1000,'SALES REPORT'!$E$2:$E1000,E$4,'SALES REPORT'!$F$2:$F1000,$B13) -> 4 | F13: =SUMIFS('SALES REPORT'!$G$2:$G1000,'SALES REPORT'!$E$2:$E1000,F$4,'SALES REPORT'!$F$2:$F1000,$B13) -> 0 | G13: =SUMIFS('SALES REPORT'!$G$2:$G1000,'SALES REPORT'!$E$2:$E1000,G$4,'SALES REPORT'!$F$2:$F1000,$B13) -> 15 | H13: =SUMIFS('SALES REPORT'!$G$2:$G1000,'SALES REPORT'!$E$2:$E1000,H$4,'SALES REPORT'!$F$2:$F1000,$B13) -> 2 | I13: =SUMIFS('SALES REPORT'!$G$2:$G1000,'SALES REPORT'!$E$2:$E1000,I$4,'SALES REPORT'!$F$2:$F1000,$B13) -> 8 | J13: =SUMIFS('SALES REPORT'!$G$2:$G1000,'SALES REPORT'!$E$2:$E1000,J$4,'SALES REPORT'!$F$2:$F1000,$B13) -> 0 | ... R13: =SUMIFS('SALES REPORT'!$G$2:$G1000,'SALES REPORT'!$E$2:$E1000,R$4,'SALES REPORT'!$F$2:$F1000,$B13) -> 1
B14: Kidney Tea | C14: =SUMIFS('SALES REPORT'!$G$2:$G1000,'SALES REPORT'!$E$2:$E1000,C$4,'SALES REPORT'!$F$2:$F1000,$B14) -> 0 | D14: =SUMIFS('SALES REPORT'!$G$2:$G1000,'SALES REPORT'!$E$2:$E1000,D$4,'SALES REPORT'!$F$2:$F1000,$B14) -> 0 | E14: =SUMIFS('SALES REPORT'!$G$2:$G1000,'SALES REPORT'!$E$2:$E1000,E$4,'SALES REPORT'!$F$2:$F1000,$B14) -> 0 | F14: =SUMIFS('SALES REPORT'!$G$2:$G1000,'SALES REPORT'!$E$2:$E1000,F$4,'SALES REPORT'!$F$2:$F1000,$B14) -> 0 | G14: =SUMIFS('SALES REPORT'!$G$2:$G1000,'SALES REPORT'!$E$2:$E1000,G$4,'SALES REPORT'!$F$2:$F1000,$B14) -> 1 | H14: =SUMIFS('SALES REPORT'!$G$2:$G1000,'SALES REPORT'!$E$2:$E1000,H$4,'SALES REPORT'!$F$2:$F1000,$B14) -> 1 | I14: =SUMIFS('SALES REPORT'!$G$2:$G1000,'SALES REPORT'!$E$2:$E1000,I$4,'SALES REPORT'!$F$2:$F1000,$B14) -> 3 | J14: =SUMIFS('SALES REPORT'!$G$2:$G1000,'SALES REPORT'!$E$2:$E1000,J$4,'SALES REPORT'!$F$2:$F1000,$B14) -> 2 | ... R14: =SUMIFS('SALES REPORT'!$G$2:$G1000,'SALES REPORT'!$E$2:$E1000,R$4,'SALES REPORT'!$F$2:$F1000,$B14) -> 0
B15: Liver Tea | C15: =SUMIFS('SALES REPORT'!$G$2:$G1000,'SALES REPORT'!$E$2:$E1000,C$4,'SALES REPORT'!$F$2:$F1000,$B15) -> 0 | D15: =SUMIFS('SALES REPORT'!$G$2:$G1000,'SALES REPORT'!$E$2:$E1000,D$4,'SALES REPORT'!$F$2:$F1000,$B15) -> 3 | E15: =SUMIFS('SALES REPORT'!$G$2:$G1000,'SALES REPORT'!$E$2:$E1000,E$4,'SALES REPORT'!$F$2:$F1000,$B15) -> 0 | F15: =SUMIFS('SALES REPORT'!$G$2:$G1000,'SALES REPORT'!$E$2:$E1000,F$4,'SALES REPORT'!$F$2:$F1000,$B15) -> 0 | G15: =SUMIFS('SALES REPORT'!$G$2:$G1000,'SALES REPORT'!$E$2:$E1000,G$4,'SALES REPORT'!$F$2:$F1000,$B15) -> 1 | H15: =SUMIFS('SALES REPORT'!$G$2:$G1000,'SALES REPORT'!$E$2:$E1000,H$4,'SALES REPORT'!$F$2:$F1000,$B15) -> 3 | I15: =SUMIFS('SALES REPORT'!$G$2:$G1000,'SALES REPORT'!$E$2:$E1000,I$4,'SALES REPORT'!$F$2:$F1000,$B15) -> 0 | J15: =SUMIFS('SALES REPORT'!$G$2:$G1000,'SALES REPORT'!$E$2:$E1000,J$4,'SALES REPORT'!$F$2:$F1000,$B15) -> 0 | ... R15: =SUMIFS('SALES REPORT'!$G$2:$G1000,'SALES REPORT'!$E$2:$E1000,R$4,'SALES REPORT'!$F$2:$F1000,$B15) -> 0
B16: Tea For Men | C16: =SUMIFS('SALES REPORT'!$G$2:$G1000,'SALES REPORT'!$E$2:$E1000,C$4,'SALES REPORT'!$F$2:$F1000,$B16) -> 0 | D16: =SUMIFS('SALES REPORT'!$G$2:$G1000,'SALES REPORT'!$E$2:$E1000,D$4,'SALES REPORT'!$F$2:$F1000,$B16) -> 5 | E16: =SUMIFS('SALES REPORT'!$G$2:$G1000,'SALES REPORT'!$E$2:$E1000,E$4,'SALES REPORT'!$F$2:$F1000,$B16) -> 1 | F16: =SUMIFS('SALES REPORT'!$G$2:$G1000,'SALES REPORT'!$E$2:$E1000,F$4,'SALES REPORT'!$F$2:$F1000,$B16) -> 0 | G16: =SUMIFS('SALES REPORT'!$G$2:$G1000,'SALES REPORT'!$E$2:$E1000,G$4,'SALES REPORT'!$F$2:$F1000,$B16) -> 9 | H16: =SUMIFS('SALES REPORT'!$G$2:$G1000,'SALES REPORT'!$E$2:$E1000,H$4,'SALES REPORT'!$F$2:$F1000,$B16) -> 0 | I16: =SUMIFS('SALES REPORT'!$G$2:$G1000,'SALES REPORT'!$E$2:$E1000,I$4,'SALES REPORT'!$F$2:$F1000,$B16) -> 10 | J16: =SUMIFS('SALES REPORT'!$G$2:$G1000,'SALES REPORT'!$E$2:$E1000,J$4,'SALES REPORT'!$F$2:$F1000,$B16) -> 0 | ... R16: =SUMIFS('SALES REPORT'!$G$2:$G1000,'SALES REPORT'!$E$2:$E1000,R$4,'SALES REPORT'!$F$2:$F1000,$B16) -> 0
B17: Bp Tea | C17: =SUMIFS('SALES REPORT'!$G$2:$G1000,'SALES REPORT'!$E$2:$E1000,C$4,'SALES REPORT'!$F$2:$F1000,$B17) -> 0 | D17: =SUMIFS('SALES REPORT'!$G$2:$G1000,'SALES REPORT'!$E$2:$E1000,D$4,'SALES REPORT'!$F$2:$F1000,$B17) -> 3 | E17: =SUMIFS('SALES REPORT'!$G$2:$G1000,'SALES REPORT'!$E$2:$E1000,E$4,'SALES REPORT'!$F$2:$F1000,$B17) -> 0 | F17: =SUMIFS('SALES REPORT'!$G$2:$G1000,'SALES REPORT'!$E$2:$E1000,F$4,'SALES REPORT'!$F$2:$F1000,$B17) -> 0 | G17: =SUMIFS('SALES REPORT'!$G$2:$G1000,'SALES REPORT'!$E$2:$E1000,G$4,'SALES REPORT'!$F$2:$F1000,$B17) -> 9 | H17: =SUMIFS('SALES REPORT'!$G$2:$G1000,'SALES REPORT'!$E$2:$E1000,H$4,'SALES REPORT'!$F$2:$F1000,$B17) -> 1 | I17: =SUMIFS('SALES REPORT'!$G$2:$G1000,'SALES REPORT'!$E$2:$E1000,I$4,'SALES REPORT'!$F$2:$F1000,$B17) -> 0 | J17: =SUMIFS('SALES REPORT'!$G$2:$G1000,'SALES REPORT'!$E$2:$E1000,J$4,'SALES REPORT'!$F$2:$F1000,$B17) -> 0 | ... R17: =SUMIFS('SALES REPORT'!$G$2:$G1000,'SALES REPORT'!$E$2:$E1000,R$4,'SALES REPORT'!$F$2:$F1000,$B17) -> 1
B18: Power Bank | C18: =SUMIFS('SALES REPORT'!$G$2:$G1000,'SALES REPORT'!$E$2:$E1000,C$4,'SALES REPORT'!$F$2:$F1000,$B18) -> 0 | D18: =SUMIFS('SALES REPORT'!$G$2:$G1000,'SALES REPORT'!$E$2:$E1000,D$4,'SALES REPORT'!$F$2:$F1000,$B18) -> 0 | E18: =SUMIFS('SALES REPORT'!$G$2:$G1000,'SALES REPORT'!$E$2:$E1000,E$4,'SALES REPORT'!$F$2:$F1000,$B18) -> 0 | F18: =SUMIFS('SALES REPORT'!$G$2:$G1000,'SALES REPORT'!$E$2:$E1000,F$4,'SALES REPORT'!$F$2:$F1000,$B18) -> 0 | G18: =SUMIFS('SALES REPORT'!$G$2:$G1000,'SALES REPORT'!$E$2:$E1000,G$4,'SALES REPORT'!$F$2:$F1000,$B18) -> 1 | H18: =SUMIFS('SALES REPORT'!$G$2:$G1000,'SALES REPORT'!$E$2:$E1000,H$4,'SALES REPORT'!$F$2:$F1000,$B18) -> 0 | I18: =SUMIFS('SALES REPORT'!$G$2:$G1000,'SALES REPORT'!$E$2:$E1000,I$4,'SALES REPORT'!$F$2:$F1000,$B18) -> 0 | J18: =SUMIFS('SALES REPORT'!$G$2:$G1000,'SALES REPORT'!$E$2:$E1000,J$4,'SALES REPORT'!$F$2:$F1000,$B18) -> 0 | ... R18: =SUMIFS('SALES REPORT'!$G$2:$G1000,'SALES REPORT'!$E$2:$E1000,R$4,'SALES REPORT'!$F$2:$F1000,$B18) -> 0
B19: Solar Generator | C19: =SUMIFS('SALES REPORT'!$G$2:$G1000,'SALES REPORT'!$E$2:$E1000,C$4,'SALES REPORT'!$F$2:$F1000,$B19) -> 0 | D19: =SUMIFS('SALES REPORT'!$G$2:$G1000,'SALES REPORT'!$E$2:$E1000,D$4,'SALES REPORT'!$F$2:$F1000,$B19) -> 1 | E19: =SUMIFS('SALES REPORT'!$G$2:$G1000,'SALES REPORT'!$E$2:$E1000,E$4,'SALES REPORT'!$F$2:$F1000,$B19) -> 0 | F19: =SUMIFS('SALES REPORT'!$G$2:$G1000,'SALES REPORT'!$E$2:$E1000,F$4,'SALES REPORT'!$F$2:$F1000,$B19) -> 0 | G19: =SUMIFS('SALES REPORT'!$G$2:$G1000,'SALES REPORT'!$E$2:$E1000,G$4,'SALES REPORT'!$F$2:$F1000,$B19) -> 0 | H19: =SUMIFS('SALES REPORT'!$G$2:$G1000,'SALES REPORT'!$E$2:$E1000,H$4,'SALES REPORT'!$F$2:$F1000,$B19) -> 0 | I19: =SUMIFS('SALES REPORT'!$G$2:$G1000,'SALES REPORT'!$E$2:$E1000,I$4,'SALES REPORT'!$F$2:$F1000,$B19) -> 3 | J19: =SUMIFS('SALES REPORT'!$G$2:$G1000,'SALES REPORT'!$E$2:$E1000,J$4,'SALES REPORT'!$F$2:$F1000,$B19) -> 0 | ... R19: =SUMIFS('SALES REPORT'!$G$2:$G1000,'SALES REPORT'!$E$2:$E1000,R$4,'SALES REPORT'!$F$2:$F1000,$B19) -> 1
B20: Pillow | C20: =SUMIFS('SALES REPORT'!$G$2:$G1000,'SALES REPORT'!$E$2:$E1000,C$4,'SALES REPORT'!$F$2:$F1000,$B20) -> 0 | D20: =SUMIFS('SALES REPORT'!$G$2:$G1000,'SALES REPORT'!$E$2:$E1000,D$4,'SALES REPORT'!$F$2:$F1000,$B20) -> 2 | E20: =SUMIFS('SALES REPORT'!$G$2:$G1000,'SALES REPORT'!$E$2:$E1000,E$4,'SALES REPORT'!$F$2:$F1000,$B20) -> 0 | F20: =SUMIFS('SALES REPORT'!$G$2:$G1000,'SALES REPORT'!$E$2:$E1000,F$4,'SALES REPORT'!$F$2:$F1000,$B20) -> 0 | G20: =SUMIFS('SALES REPORT'!$G$2:$G1000,'SALES REPORT'!$E$2:$E1000,G$4,'SALES REPORT'!$F$2:$F1000,$B20) -> 0 | H20: =SUMIFS('SALES REPORT'!$G$2:$G1000,'SALES REPORT'!$E$2:$E1000,H$4,'SALES REPORT'!$F$2:$F1000,$B20) -> 0 | I20: =SUMIFS('SALES REPORT'!$G$2:$G1000,'SALES REPORT'!$E$2:$E1000,I$4,'SALES REPORT'!$F$2:$F1000,$B20) -> 0 | J20: =SUMIFS('SALES REPORT'!$G$2:$G1000,'SALES REPORT'!$E$2:$E1000,J$4,'SALES REPORT'!$F$2:$F1000,$B20) -> 0 | ... R20: =SUMIFS('SALES REPORT'!$G$2:$G1000,'SALES REPORT'!$E$2:$E1000,R$4,'SALES REPORT'!$F$2:$F1000,$B20) -> 0
B21: Sperm Booster | C21: =SUMIFS('SALES REPORT'!$G$2:$G1000,'SALES REPORT'!$E$2:$E1000,C$4,'SALES REPORT'!$F$2:$F1000,$B21) -> 0 | D21: =SUMIFS('SALES REPORT'!$G$2:$G1000,'SALES REPORT'!$E$2:$E1000,D$4,'SALES REPORT'!$F$2:$F1000,$B21) -> 4 | E21: =SUMIFS('SALES REPORT'!$G$2:$G1000,'SALES REPORT'!$E$2:$E1000,E$4,'SALES REPORT'!$F$2:$F1000,$B21) -> 0 | F21: =SUMIFS('SALES REPORT'!$G$2:$G1000,'SALES REPORT'!$E$2:$E1000,F$4,'SALES REPORT'!$F$2:$F1000,$B21) -> 0 | G21: =SUMIFS('SALES REPORT'!$G$2:$G1000,'SALES REPORT'!$E$2:$E1000,G$4,'SALES REPORT'!$F$2:$F1000,$B21) -> 3 | H21: =SUMIFS('SALES REPORT'!$G$2:$G1000,'SALES REPORT'!$E$2:$E1000,H$4,'SALES REPORT'!$F$2:$F1000,$B21) -> 0 | I21: =SUMIFS('SALES REPORT'!$G$2:$G1000,'SALES REPORT'!$E$2:$E1000,I$4,'SALES REPORT'!$F$2:$F1000,$B21) -> 2 | J21: =SUMIFS('SALES REPORT'!$G$2:$G1000,'SALES REPORT'!$E$2:$E1000,J$4,'SALES REPORT'!$F$2:$F1000,$B21) -> 0 | ... R21: =SUMIFS('SALES REPORT'!$G$2:$G1000,'SALES REPORT'!$E$2:$E1000,R$4,'SALES REPORT'!$F$2:$F1000,$B21) -> 0
B22: Indigestion Tea | C22: =SUMIFS('SALES REPORT'!$G$2:$G1000,'SALES REPORT'!$E$2:$E1000,C$4,'SALES REPORT'!$F$2:$F1000,$B22) -> 0 | D22: =SUMIFS('SALES REPORT'!$G$2:$G1000,'SALES REPORT'!$E$2:$E1000,D$4,'SALES REPORT'!$F$2:$F1000,$B22) -> 0 | E22: =SUMIFS('SALES REPORT'!$G$2:$G1000,'SALES REPORT'!$E$2:$E1000,E$4,'SALES REPORT'!$F$2:$F1000,$B22) -> 0 | F22: =SUMIFS('SALES REPORT'!$G$2:$G1000,'SALES REPORT'!$E$2:$E1000,F$4,'SALES REPORT'!$F$2:$F1000,$B22) -> 0 | G22: =SUMIFS('SALES REPORT'!$G$2:$G1000,'SALES REPORT'!$E$2:$E1000,G$4,'SALES REPORT'!$F$2:$F1000,$B22) -> 0 | H22: =SUMIFS('SALES REPORT'!$G$2:$G1000,'SALES REPORT'!$E$2:$E1000,H$4,'SALES REPORT'!$F$2:$F1000,$B22) -> 1 | I22: =SUMIFS('SALES REPORT'!$G$2:$G1000,'SALES REPORT'!$E$2:$E1000,I$4,'SALES REPORT'!$F$2:$F1000,$B22) -> 0 | J22: =SUMIFS('SALES REPORT'!$G$2:$G1000,'SALES REPORT'!$E$2:$E1000,J$4,'SALES REPORT'!$F$2:$F1000,$B22) -> 0 | ... R22: =SUMIFS('SALES REPORT'!$G$2:$G1000,'SALES REPORT'!$E$2:$E1000,R$4,'SALES REPORT'!$F$2:$F1000,$B22) -> 0
B23: Solar Generator small | C23: =SUMIFS('SALES REPORT'!$G$2:$G1000,'SALES REPORT'!$E$2:$E1000,C$4,'SALES REPORT'!$F$2:$F1000,$B23) -> 0 | D23: =SUMIFS('SALES REPORT'!$G$2:$G1000,'SALES REPORT'!$E$2:$E1000,D$4,'SALES REPORT'!$F$2:$F1000,$B23) -> 0 | E23: =SUMIFS('SALES REPORT'!$G$2:$G1000,'SALES REPORT'!$E$2:$E1000,E$4,'SALES REPORT'!$F$2:$F1000,$B23) -> 0 | F23: =SUMIFS('SALES REPORT'!$G$2:$G1000,'SALES REPORT'!$E$2:$E1000,F$4,'SALES REPORT'!$F$2:$F1000,$B23) -> 0 | G23: =SUMIFS('SALES REPORT'!$G$2:$G1000,'SALES REPORT'!$E$2:$E1000,G$4,'SALES REPORT'!$F$2:$F1000,$B23) -> 0 | H23: =SUMIFS('SALES REPORT'!$G$2:$G1000,'SALES REPORT'!$E$2:$E1000,H$4,'SALES REPORT'!$F$2:$F1000,$B23) -> 0 | I23: =SUMIFS('SALES REPORT'!$G$2:$G1000,'SALES REPORT'!$E$2:$E1000,I$4,'SALES REPORT'!$F$2:$F1000,$B23) -> 0 | J23: =SUMIFS('SALES REPORT'!$G$2:$G1000,'SALES REPORT'!$E$2:$E1000,J$4,'SALES REPORT'!$F$2:$F1000,$B23) -> 0 | ... R23: =SUMIFS('SALES REPORT'!$G$2:$G1000,'SALES REPORT'!$E$2:$E1000,R$4,'SALES REPORT'!$F$2:$F1000,$B23) -> 0
B24: Lavender Skin | C24: =SUMIFS('SALES REPORT'!$G$2:$G1000,'SALES REPORT'!$E$2:$E1000,C$4,'SALES REPORT'!$F$2:$F1000,$B24) -> 0 | D24: =SUMIFS('SALES REPORT'!$G$2:$G1000,'SALES REPORT'!$E$2:$E1000,D$4,'SALES REPORT'!$F$2:$F1000,$B24) -> 1 | E24: =SUMIFS('SALES REPORT'!$G$2:$G1000,'SALES REPORT'!$E$2:$E1000,E$4,'SALES REPORT'!$F$2:$F1000,$B24) -> 0 | F24: =SUMIFS('SALES REPORT'!$G$2:$G1000,'SALES REPORT'!$E$2:$E1000,F$4,'SALES REPORT'!$F$2:$F1000,$B24) -> 0 | G24: =SUMIFS('SALES REPORT'!$G$2:$G1000,'SALES REPORT'!$E$2:$E1000,G$4,'SALES REPORT'!$F$2:$F1000,$B24) -> 0 | H24: =SUMIFS('SALES REPORT'!$G$2:$G1000,'SALES REPORT'!$E$2:$E1000,H$4,'SALES REPORT'!$F$2:$F1000,$B24) -> 0 | I24: =SUMIFS('SALES REPORT'!$G$2:$G1000,'SALES REPORT'!$E$2:$E1000,I$4,'SALES REPORT'!$F$2:$F1000,$B24) -> 0 | J24: =SUMIFS('SALES REPORT'!$G$2:$G1000,'SALES REPORT'!$E$2:$E1000,J$4,'SALES REPORT'!$F$2:$F1000,$B24) -> 0 | ... R24: =SUMIFS('SALES REPORT'!$G$2:$G1000,'SALES REPORT'!$E$2:$E1000,R$4,'SALES REPORT'!$F$2:$F1000,$B24) -> 0
B25: Small Blender | C25: =SUMIFS('SALES REPORT'!$G$2:$G1000,'SALES REPORT'!$E$2:$E1000,C$4,'SALES REPORT'!$F$2:$F1000,$B25) -> 0 | D25: =SUMIFS('SALES REPORT'!$G$2:$G1000,'SALES REPORT'!$E$2:$E1000,D$4,'SALES REPORT'!$F$2:$F1000,$B25) -> 1 | E25: =SUMIFS('SALES REPORT'!$G$2:$G1000,'SALES REPORT'!$E$2:$E1000,E$4,'SALES REPORT'!$F$2:$F1000,$B25) -> 0 | F25: =SUMIFS('SALES REPORT'!$G$2:$G1000,'SALES REPORT'!$E$2:$E1000,F$4,'SALES REPORT'!$F$2:$F1000,$B25) -> 0 | G25: =SUMIFS('SALES REPORT'!$G$2:$G1000,'SALES REPORT'!$E$2:$E1000,G$4,'SALES REPORT'!$F$2:$F1000,$B25) -> 0 | H25: =SUMIFS('SALES REPORT'!$G$2:$G1000,'SALES REPORT'!$E$2:$E1000,H$4,'SALES REPORT'!$F$2:$F1000,$B25) -> 0 | I25: =SUMIFS('SALES REPORT'!$G$2:$G1000,'SALES REPORT'!$E$2:$E1000,I$4,'SALES REPORT'!$F$2:$F1000,$B25) -> 1 | J25: =SUMIFS('SALES REPORT'!$G$2:$G1000,'SALES REPORT'!$E$2:$E1000,J$4,'SALES REPORT'!$F$2:$F1000,$B25) -> 0 | ... R25: =SUMIFS('SALES REPORT'!$G$2:$G1000,'SALES REPORT'!$E$2:$E1000,R$4,'SALES REPORT'!$F$2:$F1000,$B25) -> 0
B26: Clipper | C26: =SUMIFS('SALES REPORT'!$G$2:$G1000,'SALES REPORT'!$E$2:$E1000,C$4,'SALES REPORT'!$F$2:$F1000,$B26) -> 0 | D26: =SUMIFS('SALES REPORT'!$G$2:$G1000,'SALES REPORT'!$E$2:$E1000,D$4,'SALES REPORT'!$F$2:$F1000,$B26) -> 0 | E26: =SUMIFS('SALES REPORT'!$G$2:$G1000,'SALES REPORT'!$E$2:$E1000,E$4,'SALES REPORT'!$F$2:$F1000,$B26) -> 0 | F26: =SUMIFS('SALES REPORT'!$G$2:$G1000,'SALES REPORT'!$E$2:$E1000,F$4,'SALES REPORT'!$F$2:$F1000,$B26) -> 0 | G26: =SUMIFS('SALES REPORT'!$G$2:$G1000,'SALES REPORT'!$E$2:$E1000,G$4,'SALES REPORT'!$F$2:$F1000,$B26) -> 1 | H26: =SUMIFS('SALES REPORT'!$G$2:$G1000,'SALES REPORT'!$E$2:$E1000,H$4,'SALES REPORT'!$F$2:$F1000,$B26) -> 0 | I26: =SUMIFS('SALES REPORT'!$G$2:$G1000,'SALES REPORT'!$E$2:$E1000,I$4,'SALES REPORT'!$F$2:$F1000,$B26) -> 0 | J26: =SUMIFS('SALES REPORT'!$G$2:$G1000,'SALES REPORT'!$E$2:$E1000,J$4,'SALES REPORT'!$F$2:$F1000,$B26) -> 0 | ... R26: =SUMIFS('SALES REPORT'!$G$2:$G1000,'SALES REPORT'!$E$2:$E1000,R$4,'SALES REPORT'!$F$2:$F1000,$B26) -> 0
B27: Pile Tea | C27: =SUMIFS('SALES REPORT'!$G$2:$G1000,'SALES REPORT'!$E$2:$E1000,C$4,'SALES REPORT'!$F$2:$F1000,$B27) -> 0 | D27: =SUMIFS('SALES REPORT'!$G$2:$G1000,'SALES REPORT'!$E$2:$E1000,D$4,'SALES REPORT'!$F$2:$F1000,$B27) -> 0 | E27: =SUMIFS('SALES REPORT'!$G$2:$G1000,'SALES REPORT'!$E$2:$E1000,E$4,'SALES REPORT'!$F$2:$F1000,$B27) -> 1 | F27: =SUMIFS('SALES REPORT'!$G$2:$G1000,'SALES REPORT'!$E$2:$E1000,F$4,'SALES REPORT'!$F$2:$F1000,$B27) -> 0 | G27: =SUMIFS('SALES REPORT'!$G$2:$G1000,'SALES REPORT'!$E$2:$E1000,G$4,'SALES REPORT'!$F$2:$F1000,$B27) -> 0 | H27: =SUMIFS('SALES REPORT'!$G$2:$G1000,'SALES REPORT'!$E$2:$E1000,H$4,'SALES REPORT'!$F$2:$F1000,$B27) -> 0 | I27: =SUMIFS('SALES REPORT'!$G$2:$G1000,'SALES REPORT'!$E$2:$E1000,I$4,'SALES REPORT'!$F$2:$F1000,$B27) -> 0 | J27: =SUMIFS('SALES REPORT'!$G$2:$G1000,'SALES REPORT'!$E$2:$E1000,J$4,'SALES REPORT'!$F$2:$F1000,$B27) -> 0 | ... R27: =SUMIFS('SALES REPORT'!$G$2:$G1000,'SALES REPORT'!$E$2:$E1000,R$4,'SALES REPORT'!$F$2:$F1000,$B27) -> 0
B28: Bladder Tea | C28: =SUMIFS('SALES REPORT'!$G$2:$G1000,'SALES REPORT'!$E$2:$E1000,C$4,'SALES REPORT'!$F$2:$F1000,$B28) -> 0 | D28: =SUMIFS('SALES REPORT'!$G$2:$G1000,'SALES REPORT'!$E$2:$E1000,D$4,'SALES REPORT'!$F$2:$F1000,$B28) -> 0 | E28: =SUMIFS('SALES REPORT'!$G$2:$G1000,'SALES REPORT'!$E$2:$E1000,E$4,'SALES REPORT'!$F$2:$F1000,$B28) -> 0 | F28: =SUMIFS('SALES REPORT'!$G$2:$G1000,'SALES REPORT'!$E$2:$E1000,F$4,'SALES REPORT'!$F$2:$F1000,$B28) -> 0 | G28: =SUMIFS('SALES REPORT'!$G$2:$G1000,'SALES REPORT'!$E$2:$E1000,G$4,'SALES REPORT'!$F$2:$F1000,$B28) -> 0 | H28: =SUMIFS('SALES REPORT'!$G$2:$G1000,'SALES REPORT'!$E$2:$E1000,H$4,'SALES REPORT'!$F$2:$F1000,$B28) -> 0 | I28: =SUMIFS('SALES REPORT'!$G$2:$G1000,'SALES REPORT'!$E$2:$E1000,I$4,'SALES REPORT'!$F$2:$F1000,$B28) -> 1 | J28: =SUMIFS('SALES REPORT'!$G$2:$G1000,'SALES REPORT'!$E$2:$E1000,J$4,'SALES REPORT'!$F$2:$F1000,$B28) -> 0 | ... R28: =SUMIFS('SALES REPORT'!$G$2:$G1000,'SALES REPORT'!$E$2:$E1000,R$4,'SALES REPORT'!$F$2:$F1000,$B28) -> 0
B29: Anti aging Tea | C29: =SUMIFS('SALES REPORT'!$G$2:$G1000,'SALES REPORT'!$E$2:$E1000,C$4,'SALES REPORT'!$F$2:$F1000,$B29) -> 0 | D29: =SUMIFS('SALES REPORT'!$G$2:$G1000,'SALES REPORT'!$E$2:$E1000,D$4,'SALES REPORT'!$F$2:$F1000,$B29) -> 2 | E29: =SUMIFS('SALES REPORT'!$G$2:$G1000,'SALES REPORT'!$E$2:$E1000,E$4,'SALES REPORT'!$F$2:$F1000,$B29) -> 0 | F29: =SUMIFS('SALES REPORT'!$G$2:$G1000,'SALES REPORT'!$E$2:$E1000,F$4,'SALES REPORT'!$F$2:$F1000,$B29) -> 0 | G29: =SUMIFS('SALES REPORT'!$G$2:$G1000,'SALES REPORT'!$E$2:$E1000,G$4,'SALES REPORT'!$F$2:$F1000,$B29) -> 0 | H29: =SUMIFS('SALES REPORT'!$G$2:$G1000,'SALES REPORT'!$E$2:$E1000,H$4,'SALES REPORT'!$F$2:$F1000,$B29) -> 0 | I29: =SUMIFS('SALES REPORT'!$G$2:$G1000,'SALES REPORT'!$E$2:$E1000,I$4,'SALES REPORT'!$F$2:$F1000,$B29) -> 0 | J29: =SUMIFS('SALES REPORT'!$G$2:$G1000,'SALES REPORT'!$E$2:$E1000,J$4,'SALES REPORT'!$F$2:$F1000,$B29) -> 0 | ... R29: =SUMIFS('SALES REPORT'!$G$2:$G1000,'SALES REPORT'!$E$2:$E1000,R$4,'SALES REPORT'!$F$2:$F1000,$B29) -> 0
B30: Bp tea | C30: =SUMIFS('SALES REPORT'!$G$2:$G1000,'SALES REPORT'!$E$2:$E1000,C$4,'SALES REPORT'!$F$2:$F1000,$B30) -> 0 | D30: =SUMIFS('SALES REPORT'!$G$2:$G1000,'SALES REPORT'!$E$2:$E1000,D$4,'SALES REPORT'!$F$2:$F1000,$B30) -> 3 | E30: =SUMIFS('SALES REPORT'!$G$2:$G1000,'SALES REPORT'!$E$2:$E1000,E$4,'SALES REPORT'!$F$2:$F1000,$B30) -> 0 | F30: =SUMIFS('SALES REPORT'!$G$2:$G1000,'SALES REPORT'!$E$2:$E1000,F$4,'SALES REPORT'!$F$2:$F1000,$B30) -> 0 | G30: =SUMIFS('SALES REPORT'!$G$2:$G1000,'SALES REPORT'!$E$2:$E1000,G$4,'SALES REPORT'!$F$2:$F1000,$B30) -> 9 | H30: =SUMIFS('SALES REPORT'!$G$2:$G1000,'SALES REPORT'!$E$2:$E1000,H$4,'SALES REPORT'!$F$2:$F1000,$B30) -> 1 | I30: =SUMIFS('SALES REPORT'!$G$2:$G1000,'SALES REPORT'!$E$2:$E1000,I$4,'SALES REPORT'!$F$2:$F1000,$B30) -> 0 | J30: =SUMIFS('SALES REPORT'!$G$2:$G1000,'SALES REPORT'!$E$2:$E1000,J$4,'SALES REPORT'!$F$2:$F1000,$B30) -> 0 | ... R30: =SUMIFS('SALES REPORT'!$G$2:$G1000,'SALES REPORT'!$E$2:$E1000,R$4,'SALES REPORT'!$F$2:$F1000,$B30) -> 1
B31: Car Airfresher | C31: =SUMIFS('SALES REPORT'!$G$2:$G1000,'SALES REPORT'!$E$2:$E1000,C$4,'SALES REPORT'!$F$2:$F1000,$B31) -> 0 | D31: =SUMIFS('SALES REPORT'!$G$2:$G1000,'SALES REPORT'!$E$2:$E1000,D$4,'SALES REPORT'!$F$2:$F1000,$B31) -> 1 | E31: =SUMIFS('SALES REPORT'!$G$2:$G1000,'SALES REPORT'!$E$2:$E1000,E$4,'SALES REPORT'!$F$2:$F1000,$B31) -> 0 | F31: =SUMIFS('SALES REPORT'!$G$2:$G1000,'SALES REPORT'!$E$2:$E1000,F$4,'SALES REPORT'!$F$2:$F1000,$B31) -> 0 | G31: =SUMIFS('SALES REPORT'!$G$2:$G1000,'SALES REPORT'!$E$2:$E1000,G$4,'SALES REPORT'!$F$2:$F1000,$B31) -> 0 | H31: =SUMIFS('SALES REPORT'!$G$2:$G1000,'SALES REPORT'!$E$2:$E1000,H$4,'SALES REPORT'!$F$2:$F1000,$B31) -> 0 | I31: =SUMIFS('SALES REPORT'!$G$2:$G1000,'SALES REPORT'!$E$2:$E1000,I$4,'SALES REPORT'!$F$2:$F1000,$B31) -> 0 | J31: =SUMIFS('SALES REPORT'!$G$2:$G1000,'SALES REPORT'!$E$2:$E1000,J$4,'SALES REPORT'!$F$2:$F1000,$B31) -> 0 | ... R31: =SUMIFS('SALES REPORT'!$G$2:$G1000,'SALES REPORT'!$E$2:$E1000,R$4,'SALES REPORT'!$F$2:$F1000,$B31) -> 0
B32: Infertility Tea | C32: =SUMIFS('SALES REPORT'!$G$2:$G1000,'SALES REPORT'!$E$2:$E1000,C$4,'SALES REPORT'!$F$2:$F1000,$B32) -> 0 | D32: =SUMIFS('SALES REPORT'!$G$2:$G1000,'SALES REPORT'!$E$2:$E1000,D$4,'SALES REPORT'!$F$2:$F1000,$B32) -> 0 | E32: =SUMIFS('SALES REPORT'!$G$2:$G1000,'SALES REPORT'!$E$2:$E1000,E$4,'SALES REPORT'!$F$2:$F1000,$B32) -> 0 | F32: =SUMIFS('SALES REPORT'!$G$2:$G1000,'SALES REPORT'!$E$2:$E1000,F$4,'SALES REPORT'!$F$2:$F1000,$B32) -> 0 | G32: =SUMIFS('SALES REPORT'!$G$2:$G1000,'SALES REPORT'!$E$2:$E1000,G$4,'SALES REPORT'!$F$2:$F1000,$B32) -> 0 | H32: =SUMIFS('SALES REPORT'!$G$2:$G1000,'SALES REPORT'!$E$2:$E1000,H$4,'SALES REPORT'!$F$2:$F1000,$B32) -> 0 | I32: =SUMIFS('SALES REPORT'!$G$2:$G1000,'SALES REPORT'!$E$2:$E1000,I$4,'SALES REPORT'!$F$2:$F1000,$B32) -> 0 | J32: =SUMIFS('SALES REPORT'!$G$2:$G1000,'SALES REPORT'!$E$2:$E1000,J$4,'SALES REPORT'!$F$2:$F1000,$B32) -> 0 | ... R32: =SUMIFS('SALES REPORT'!$G$2:$G1000,'SALES REPORT'!$E$2:$E1000,R$4,'SALES REPORT'!$F$2:$F1000,$B32) -> 0
